Workbook

Sheet 7.1.
A3: Etykiety wierszy | B3: Suma z maksymalna ilosc dla obszaru do 100 m
A4: Aeolis | B4: 205807
A5: Amazonis | B5: 191736
A6: Amenthes | B6: 523106
A7: Arabia | B7: 248833
A8: Arcadia | B8: 496080
A9: Argyre | B9: 1875653
A10: Casius | B10: 841668
A11: Cebrenia | B11: 2183320
A12: Coprates | B12: 447349
A13: Diacria | B13: 317986
A14: Elysium | B14: 489782
A15: Eridania | B15: 1302060
... A21: Mare Australe | B21: 3463843
A22: Mare Boreum | B22: 4103901 | D22: Najwiecej łącznie do 100 m^3: | E22: Mare Boreum
A23: Mare Tyrrhenum | B23: 267257
A24: Margaritifer Sinus | B24: 395946
A25: Memnonia | B25: 287399
A26: Noachis | B26: 606262
A27: Oxia Palus | B27: 294598
A28: Phaethontis | B28: 1171590
A29: Phoenicis Lacus | B29: 418261
A30: Sinus Sabaeus | B30: 107071
A31: Syrtis Major | B31: 287954
A32: Tharsis | B32: 192005
A33: Thaumasia | B33: 1684072
A34: Suma końcowa | B34: 25595945

Sheet 7.2.
B2: dla kazdego lazika musimy zrobic roznice miedzy pierwszym wydobyciem a ostatnim i sprawdzic która jest najdluzsza
A3: Etykiety wierszy | B3: Minimum data_pomiaru | C3: Maksimum data_pomiaru
A4: Dawn 3 | B4: 61208 | C4: 61395 | D4: =C4-B4 -> 187
A5: Dawn 4 | B5: 61224 | C5: 63339 | D5: =C5-B5 -> 2115 | G5: 7.2. | H5: Spirit14
A6: Dawn 6 | B6: 61277 | C6: 63541 | D6: =C6-B6 -> 2264 | G6: 60873 | H6: 64491
A7: Dawn 9 | B7: 61528 | C7: 61687 | D7: =C7-B7 -> 159
A8: Deimos 10 | B8: 58462 | C8: 61106 | D8: =C8-B8 -> 2644
A9: Deimos 11 | B9: 58491 | C9: 61435 | D9: =C9-B9 -> 2944
A10: Deimos 13 | B10: 58762 | C10: 59172 | D10: =C10-B10 -> 410
A11: Deimos 14 | B11: 58768 | C11: 60523 | D11: =C11-B11 -> 1755
A12: Deimos 3 | B12: 58105 | C12: 59708 | D12: =C12-B12 -> 1603
A13: Deimos 4 | B13: 58259 | C13: 59123 | D13: =C13-B13 -> 864
A14: Deimos 8 | B14: 58279 | C14: 59039 | D14: =C14-B14 -> 760
A15: Mariner 10 | B15: 55706 | C15: 58917 | D15: =C15-B15 -> 3211
A16: Mariner 11 | B16: 55887 | C16: 56806 | D16: =C16-B16 -> 919
A17: Mariner 12 | B17: 56169 | C17: 57472 | D17: =C17-B17 -> 1303
A18: Mariner 13 | B18: 56449 | C18: 57360 | D18: =C18-B18 -> 911
... A89: Spirit 13 | B89: 60668 | C89: 61466 | D89: =C89-B89 -> 798
A90: Spirit 14 | B90: 60873 | C90: 64491 | D90: =C90-B90 -> 3618 | E90: Spirit14
A91: Spirit 15 | B91: 60982 | C91: 61134 | D91: =C91-B91 -> 152
A92: Spirit 16 | B92: 61079 | C92: 61887 | D92: =C92-B92 -> 808
A93: Spirit 5 | B93: 59878 | C93: 62495 | D93: =C93-B93 -> 2617
A94: Spirit 6 | B94: 60083 | C94: 62797 | D94: =C94-B94 -> 2714
A95: Spirit 7 | B95: 60167 | C95: 60656 | D95: =C95-B95 -> 489
A96: Viking 10 | B96: 57066 | C96: 58552 | D96: =C96-B96 -> 1486
A97: Viking 13 | B97: 57362 | C97: 58173 | D97: =C97-B97 -> 811
A98: Viking 15 | B98: 57404 | C98: 58565 | D98: =C98-B98 -> 1161
A99: Viking 17 | B99: 57501 | C99: 57755 | D99: =C99-B99 -> 254
A100: Viking 2 | B100: 56140 | C100: 56966 | D100: =C100-B100 -> 826
A101: Viking 4 | B101: 56367 | C101: 57008 | D101: =C101-B101 -> 641
A102: Viking 5 | B102: 56515 | C102: 56866 | D102: =C102-B102 -> 351
... A104: Viking 8 | B104: 56799 | C104: 59676 | D104: =C104-B104 -> 2877
A105: Suma końcowa | B105: 54984 | C105: 66063

Sheet 7.3.
A3: Liczba z roznice lat od wyslania a pracy lazika | B3: Etykiety kolumn
A4: Etykiety wierszy | B4: 0 | C4: 1 | D4: 2 | E4: 3 | F4: 4 | G4: 5 | H4: 6 | I4: 7 | J4: 8 | K4: 9 | L4: 10 | M4: 11 | N4: Suma końcowa | P4: jeśli 0 nie występuje ani razu to znaczy że żaden łazik nie był w tym samym roku na obszarze marsa
A5: Aeolis | C5: 25 | D5: 22 | E5: 18 | F5: 11 | G5: 5 | H5: 1 | I5: 1 | J5: 1 | N5: 84 | P5: Aeolis
A6: Amazonis | C6: 23 | D6: 17 | E6: 9 | F6: 2 | G6: 7 | H6: 3 | I6: 5 | J6: 5 | N6: 71 | P6: Amazonis
A7: Amenthes | B7: 2 | C7: 39 | D7: 54 | E7: 44 | F7: 41 | G7: 28 | H7: 15 | I7: 15 | J7: 9 | K7: 1 | N7: 248 | P7: Arabia
A8: Arabia | C8: 12 | D8: 29 | E8: 29 | F8: 18 | G8: 6 | H8: 4 | I8: 2 | J8: 2 | K8: 2 | L8: 2 | M8: 1 | N8: 107 | P8: Elysium
A9: Arcadia | B9: 1 | C9: 20 | D9: 22 | E9: 20 | F9: 11 | G9: 6 | H9: 6 | I9: 6 | J9: 2 | N9: 94 | P9: Eridania
A10: Argyre | B10: 6 | C10: 82 | D10: 91 | E10: 46 | F10: 31 | G10: 18 | H10: 24 | I10: 15 | J10: 4 | K10: 1 | N10: 318 | P10: Mare Tyrrhenum
A11: Casius | B11: 3 | C11: 36 | D11: 40 | E11: 24 | F11: 20 | G11: 16 | H11: 9 | I11: 7 | J11: 7 | K11: 3 | N11: 165 | P11: Sinus Sabaeus
A12: Cebrenia | B12: 2 | C12: 67 | D12: 86 | E12: 66 | F12: 32 | G12: 46 | H12: 33 | I12: 32 | J12: 22 | N12: 386 | P12: Syrtis Major
A13: Coprates | B13: 3 | C13: 24 | D13: 38 | E13: 18 | F13: 18 | G13: 21 | H13: 14 | I13: 17 | J13: 9 | K13: 7 | N13: 169
A14: Diacria | B14: 1 | C14: 15 | D14: 15 | E14: 4 | F14: 4 | G14: 9 | H14: 3 | I14: 5 | J14: 4 | N14: 60
A15: Elysium | C15: 30 | D15: 36 | E15: 26 | F15: 27 | G15: 21 | H15: 22 | I15: 12 | J15: 10 | N15: 184
A16: Eridania | C16: 29 | D16: 48 | E16: 45 | F16: 29 | G16: 19 | H16: 20 | I16: 7 | K16: 1 | N16: 198
A17: Hellas | B17: 5 | C17: 63 | D17: 70 | E17: 51 | F17: 40 | G17: 34 | H17: 7 | I17: 3 | J17: 9 | K17: 7 | L17: 5 | M17: 1 | N17: 295
A18: Iapygia | B18: 1 | C18: 18 | D18: 29 | E18: 20 | F18: 16 | G18: 11 | H18: 4 | I18: 4 | J18: 7 | K18: 4 | L18: 1 | N18: 115
A19: Ismenius Lacus | B19: 1 | C19: 16 | D19: 14 | E19: 13 | F19: 8 | G19: 20 | H19: 6 | I19: 10 | J19: 2 | K19: 1 | L19: 2 | M19: 1 | N19: 94
A20: Lunae Palus | B20: 2 | C20: 11 | D20: 18 | E20: 12 | F20: 6 | G20: 4 | H20: 7 | N20: 60
A21: Mare Acidalium | B21: 4 | C21: 22 | D21: 18 | E21: 24 | F21: 11 | G21: 6 | H21: 5 | I21: 4 | J21: 4 | K21: 5 | L21: 8 | M21: 2 | N21: 113
A22: Mare Australe | B22: 1 | C22: 67 | D22: 86 | E22: 69 | F22: 54 | G22: 37 | H22: 12 | I22: 10 | J22: 6 | K22: 9 | L22: 7 | M22: 2 | N22: 360
A23: Mare Boreum | B23: 9 | C23: 118 | D23: 89 | E23: 80 | F23: 57 | G23: 51 | H23: 43 | I23: 32 | J23: 14 | N23: 493
A24: Mare Tyrrhenum | C24: 19 | D24: 31 | E24: 16 | F24: 27 | G24: 13 | H24: 6 | I24: 2 | J24: 2 | N24: 116
A25: Margaritifer Sinus | B25: 1 | C25: 36 | D25: 47 | E25: 18 | F25: 13 | G25: 11 | H25: 9 | I25: 3 | J25: 3 | K25: 5 | N25: 146
A26: Memnonia | B26: 2 | C26: 35 | D26: 39 | E26: 15 | F26: 18 | G26: 3 | H26: 2 | I26: 1 | K26: 1 | N26: 116
A27: Noachis | B27: 1 | C27: 14 | D27: 23 | E27: 20 | F27: 10 | G27: 5 | H27: 1 | N27: 74
A28: Oxia Palus | B28: 1 | C28: 17 | D28: 27 | E28: 11 | F28: 10 | G28: 13 | H28: 11 | I28: 9 | J28: 8 | K28: 9 | L28: 3 | M28: 7 | N28: 126
A29: Phaethontis | B29: 1 | C29: 53 | D29: 90 | E29: 39 | F29: 22 | G29: 8 | H29: 2 | N29: 215
A30: Phoenicis Lacus | B30: 2 | C30: 42 | D30: 43 | E30: 39 | F30: 36 | G30: 16 | H30: 13 | I30: 5 | J30: 9 | N30: 205
A31: Sinus Sabaeus | C31: 7 | D31: 22 | E31: 13 | F31: 8 | G31: 2 | H31: 2 | J31: 2 | K31: 1 | N31: 57
A32: Syrtis Major | C32: 13 | D32: 22 | E32: 27 | F32: 18 | G32: 15 | H32: 14 | I32: 16 | J32: 6 | K32: 9 | L32: 4 | N32: 144
A33: Tharsis | B33: 4 | C33: 14 | D33: 18 | E33: 14 | F33: 5 | G33: 8 | H33: 9 | I33: 7 | J33: 7 | N33: 86
A34: Thaumasia | B34: 1 | C34: 71 | D34: 55 | E34: 38 | F34: 31 | G34: 32 | H34: 18 | I34: 17 | J34: 12 | K34: 5 | N34: 280
A35: Suma końcowa | B35: 54 | C35: 1038 | D35: 1239 | E35: 868 | F35: 634 | G35: 491 | H35: 325 | I35: 247 | J35: 166 | K35: 71 | L35: 32 | M35: 14 | N35: 5179

Sheet 7.4.
A1: Lądowanie na półkuli | B1: S | D1: wpisane sa tylko laziki które ladowaly na polkuli S
A3: Liczba z Praca na której polkuli | B3: Etykiety kolumn
A4: Etykiety wierszy | B4: N | C4: S | D4: Suma końcowa | E4: Czy łazik pracował a obu półkulach | F4: 0/1 czy pracowal na obu
A5: Dawn 4 | C5: 82 | D5: 82 | E5: =IF(OR(B5=0,C5=0),"Nie pracował na obu","Pracował na obu") -> Nie pracował na obu | F5: =IF(OR(B5=0,C5=0),0,1) -> 0 | G5: =IF(F5=1,A5,0) -> 0
A6: Deimos 11 | C6: 117 | D6: 117 | E6: =IF(OR(B6=0,C6=0),"Nie pracował na obu","Pracował na obu") -> Nie pracował na obu | F6: =IF(OR(B6=0,C6=0),0,1) -> 0 | G6: =IF(F6=1,A6,0) -> 0
A7: Deimos 3 | C7: 65 | D7: 65 | E7: =IF(OR(B7=0,C7=0),"Nie pracował na obu","Pracował na obu") -> Nie pracował na obu | F7: =IF(OR(B7=0,C7=0),0,1) -> 0 | G7: =IF(F7=1,A7,0) -> 0
A8: Deimos 4 | C8: 40 | D8: 40 | E8: =IF(OR(B8=0,C8=0),"Nie pracował na obu","Pracował na obu") -> Nie pracował na obu | F8: =IF(OR(B8=0,C8=0),0,1) -> 0 | G8: =IF(F8=1,A8,0) -> 0
A9: Mariner 13 | C9: 36 | D9: 36 | E9: =IF(OR(B9=0,C9=0),"Nie pracował na obu","Pracował na obu") -> Nie pracował na obu | F9: =IF(OR(B9=0,C9=0),0,1) -> 0 | G9: =IF(F9=1,A9,0) -> 0
A10: Mariner 14 | B10: 9 | C10: 67 | D10: 76 | E10: =IF(OR(B10=0,C10=0),"Nie pracował na obu","Pracował na obu") -> Pracował na obu | F10: =IF(OR(B10=0,C10=0),0,1) -> 1 | G10: =IF(F10=1,A10,0) -> Mariner 14
A11: Mariner 15 | B11: 1 | C11: 121 | D11: 122 | E11: =IF(OR(B11=0,C11=0),"Nie pracował na obu","Pracował na obu") -> Pracował na obu | F11: =IF(OR(B11=0,C11=0),0,1) -> 1 | G11: =IF(F11=1,A11,0) -> Mariner 15
A12: Mariner 16 | C12: 23 | D12: 23 | E12: =IF(OR(B12=0,C12=0),"Nie pracował na obu","Pracował na obu") -> Nie pracował na obu | F12: =IF(OR(B12=0,C12=0),0,1) -> 0 | G12: =IF(F12=1,A12,0) -> 0
A13: Mariner 20 | B13: 18 | C13: 24 | D13: 42 | E13: =IF(OR(B13=0,C13=0),"Nie pracował na obu","Pracował na obu") -> Pracował na obu | F13: =IF(OR(B13=0,C13=0),0,1) -> 1 | G13: =IF(F13=1,A13,0) -> Mariner 20
A14: Mariner 7 | C14: 19 | D14: 19 | E14: =IF(OR(B14=0,C14=0),"Nie pracował na obu","Pracował na obu") -> Nie pracował na obu | F14: =IF(OR(B14=0,C14=0),0,1) -> 0 | G14: =IF(F14=1,A14,0) -> 0
A15: Mariner 9 | C15: 93 | D15: 93 | E15: =IF(OR(B15=0,C15=0),"Nie pracował na obu","Pracował na obu") -> Nie pracował na obu | F15: =IF(OR(B15=0,C15=0),0,1) -> 0 | G15: =IF(F15=1,A15,0) -> 0
A16: Opportunity 10 | C16: 108 | D16: 108 | E16: =IF(OR(B16=0,C16=0),"Nie pracował na obu","Pracował na obu") -> Nie pracował na obu | F16: =IF(OR(B16=0,C16=0),0,1) -> 0 | G16: =IF(F16=1,A16,0) -> 0
A17: Opportunity 13 | C17: 12 | D17: 12 | E17: =IF(OR(B17=0,C17=0),"Nie pracował na obu","Pracował na obu") -> Nie pracował na obu | F17: =IF(OR(B17=0,C17=0),0,1) -> 0 | G17: =IF(F17=1,A17,0) -> 0
A18: Opportunity 15 | C18: 34 | D18: 34 | E18: =IF(OR(B18=0,C18=0),"Nie pracował na obu","Pracował na obu") -> Nie pracował na obu | F18: =IF(OR(B18=0,C18=0),0,1) -> 0 | G18: =IF(F18=1,A18,0) -> 0
A19: Opportunity 16 | C19: 19 | D19: 19 | E19: =IF(OR(B19=0,C19=0),"Nie pracował na obu","Pracował na obu") -> Nie pracował na obu | F19: =IF(OR(B19=0,C19=0),0,1) -> 0 | G19: =IF(F19=1,A19,0) -> 0
A20: Opportunity 18 | C20: 51 | D20: 51 | E20: =IF(OR(B20=0,C20=0),"Nie pracował na obu","Pracował na obu") -> Nie pracował na obu | F20: =IF(OR(B20=0,C20=0),0,1) -> 0 | G20: =IF(F20=1,A20,0) -> 0
A21: Opportunity 19 | C21: 55 | D21: 55 | E21: =IF(OR(B21=0,C21=0),"Nie pracował na obu","Pracował na obu") -> Nie pracował na obu | F21: =IF(OR(B21=0,C21=0),0,1) -> 0 | G21: =IF(F21=1,A21,0) -> 0
A22: Opportunity 3 | C22: 33 | D22: 33 | E22: =IF(OR(B22=0,C22=0),"Nie pracował na obu","Pracował na obu") -> Nie pracował na obu | F22: =IF(OR(B22=0,C22=0),0,1) -> 0 | G22: =IF(F22=1,A22,0) -> 0
A23: Opportunity 5 | C23: 35 | D23: 35 | E23: =IF(OR(B23=0,C23=0),"Nie pracował na obu","Pracował na obu") -> Nie pracował na obu | F23: =IF(OR(B23=0,C23=0),0,1) -> 0 | G23: =IF(F23=1,A23,0) -> 0
A24: Pathfinder 2 | C24: 58 | D24: 58 | E24: =IF(OR(B24=0,C24=0),"Nie pracował na obu","Pracował na obu") -> Nie pracował na obu | F24: =IF(OR(B24=0,C24=0),0,1) -> 0 | G24: =IF(F24=1,A24,0) -> 0
A25: Pathfinder 9 | C25: 75 | D25: 75 | E25: =IF(OR(B25=0,C25=0),"Nie pracował na obu","Pracował na obu") -> Nie pracował na obu | F25: =IF(OR(B25=0,C25=0),0,1) -> 0 | G25: =IF(F25=1,A25,0) -> 0
... A32: Phobos 6 | C32: 139 | D32: 139 | E32: =IF(OR(B32=0,C32=0),"Nie pracował na obu","Pracował na obu") -> Nie pracował na obu | F32: =IF(OR(B32=0,C32=0),0,1) -> 0 | G32: =IF(F32=1,A32,0) -> 0
A33: Phoenix 13 | B33: 27 | C33: 37 | D33: 64 | E33: =IF(OR(B33=0,C33=0),"Nie pracował na obu","Pracował na obu") -> Pracował na obu | F33: =IF(OR(B33=0,C33=0),0,1) -> 1 | G33: =IF(F33=1,A33,0) -> Phoenix 13
A34: Phoenix 17 | C34: 25 | D34: 25 | E34: =IF(OR(B34=0,C34=0),"Nie pracował na obu","Pracował na obu") -> Nie pracował na obu | F34: =IF(OR(B34=0,C34=0),0,1) -> 0 | G34: =IF(F34=1,A34,0) -> 0
A35: Phoenix 19 | C35: 22 | D35: 22 | E35: =IF(OR(B35=0,C35=0),"Nie pracował na obu","Pracował na obu") -> Nie pracował na obu | F35: =IF(OR(B35=0,C35=0),0,1) -> 0 | G35: =IF(F35=1,A35,0) -> 0
A36: Phoenix 22 | C36: 78 | D36: 78 | E36: =IF(OR(B36=0,C36=0),"Nie pracował na obu","Pracował na obu") -> Nie pracował na obu | F36: =IF(OR(B36=0,C36=0),0,1) -> 0 | G36: =IF(F36=1,A36,0) -> 0
A37: Phoenix 23 | C37: 30 | D37: 30 | E37: =IF(OR(B37=0,C37=0),"Nie pracował na obu","Pracował na obu") -> Nie pracował na obu | F37: =IF(OR(B37=0,C37=0),0,1) -> 0 | G37: =IF(F37=1,A37,0) -> 0
A38: Phoenix 3 | B38: 4 | C38: 5 | D38: 9 | E38: =IF(OR(B38=0,C38=0),"Nie pracował na obu","Pracował na obu") -> Pracował na obu | F38: =IF(OR(B38=0,C38=0),0,1) -> 1 | G38: =IF(F38=1,A38,0) -> Phoenix 3
A39: Phoenix 7 | C39: 55 | D39: 55 | E39: =IF(OR(B39=0,C39=0),"Nie pracował na obu","Pracował na obu") -> Nie pracował na obu | F39: =IF(OR(B39=0,C39=0),0,1) -> 0 | G39: =IF(F39=1,A39,0) -> 0
A40: Rosetta 1 | B40: 10 | C40: 25 | D40: 35 | E40: =IF(OR(B40=0,C40=0),"Nie pracował na obu","Pracował na obu") -> Pracował na obu | F40: =IF(OR(B40=0,C40=0),0,1) -> 1 | G40: =IF(F40=1,A40,0) -> Rosetta 1
A41: Rosetta 10 | C41: 40 | D41: 40 | E41: =IF(OR(B41=0,C41=0),"Nie pracował na obu","Pracował na obu") -> Nie pracował na obu | F41: =IF(OR(B41=0,C41=0),0,1) -> 0 | G41: =IF(F41=1,A41,0) -> 0
A42: Rosetta 14 | C42: 18 | D42: 18 | E42: =IF(OR(B42=0,C42=0),"Nie pracował na obu","Pracował na obu") -> Nie pracował na obu | F42: =IF(OR(B42=0,C42=0),0,1) -> 0 | G42: =IF(F42=1,A42,0) -> 0
A43: Rosetta 15 | C43: 25 | D43: 25 | E43: =IF(OR(B43=0,C43=0),"Nie pracował na obu","Pracował na obu") -> Nie pracował na obu | F43: =IF(OR(B43=0,C43=0),0,1) -> 0 | G43: =IF(F43=1,A43,0) -> 0
A44: Rosetta 16 | C44: 67 | D44: 67 | E44: =IF(OR(B44=0,C44=0),"Nie pracował na obu","Pracował na obu") -> Nie pracował na obu | F44: =IF(OR(B44=0,C44=0),0,1) -> 0 | G44: =IF(F44=1,A44,0) -> 0
A45: Rosetta 20 | C45: 21 | D45: 21 | E45: =IF(OR(B45=0,C45=0),"Nie pracował na obu","Pracował na obu") -> Nie pracował na obu | F45: =IF(OR(B45=0,C45=0),0,1) -> 0 | G45: =IF(F45=1,A45,0) -> 0
A46: Rosetta 22 | C46: 69 | D46: 69 | E46: =IF(OR(B46=0,C46=0),"Nie pracował na obu","Pracował na obu") -> Nie pracował na obu | F46: =IF(OR(B46=0,C46=0),0,1) -> 0 | G46: =IF(F46=1,A46,0) -> 0
A47: Rosetta 27 | C47: 67 | D47: 67 | E47: =IF(OR(B47=0,C47=0),"Nie pracował na obu","Pracował na obu") -> Nie pracował na obu | F47: =IF(OR(B47=0,C47=0),0,1) -> 0 | G47: =IF(F47=1,A47,0) -> 0
...

Sheet pomiary
A1: nr_lazika | B1: data_pomiaru | C1: kod_obszaru | D1: wspolrzedne | E1: glebokosc | F1: ilosc | G1: maksymalna ilosc dla obszaru do 100 m | H1: nazwa obszaru | I1: nazwa lazika | J1: współrzędne lądowania | K1: data wysłania z ziemi | L1: data pomiaru l.całkowita | M1: roznice lat od wyslania a pracy lazika | N1: Praca na której polkuli | O1: Lądowanie na półkuli
A2: 17 | B2: 58960 | C2: MC-13 | D2: 13.17N, 77.80E | E2: 344 | F2: 5622 | G2: =IF($E2 <= 100,F2,0) -> 0 | H2: =_xlfn.XLOOKUP(C2,obszary!A:A,obszary!B:B) -> Syrtis Major | I2: =_xlfn.XLOOKUP($A2,laziki!B:B,laziki!C:C) -> Viking 8 | J2: =_xlfn.XLOOKUP(I2,laziki!C:C,laziki!E:E) -> 21.27N, 90.13E | K2: =_xlfn.XLOOKUP($A2,laziki!B:B,laziki!D:D) -> 2054 | L2: =YEAR(B2) -> 2061 | M2: =L2-K2 -> 7 | N2: =IF(NOT(ISERROR(SEARCH("S",D2))),"S","N") -> N | O2: =IF(NOT(ISERROR(SEARCH("S",J2))),"S","N") -> N | P2: jeśli data wysłania z ziemi - data pomiaru = jeśli 0 to znaczy ze pomiar był robiony w tym samym roku co zostal wyslany
A3: 17 | B3: 57133 | C3: MC-14 | D3: 14.93N, 106.00E | E3: 43 | F3: 2054 | G3: =IF($E3 <= 100,F3,0) -> 2054 | H3: =_xlfn.XLOOKUP(C3,obszary!A:A,obszary!B:B) -> Amenthes | I3: =_xlfn.XLOOKUP($A3,laziki!B:B,laziki!C:C) -> Viking 8 | J3: =_xlfn.XLOOKUP(I3,laziki!C:C,laziki!E:E) -> 21.27N, 90.13E | K3: =_xlfn.XLOOKUP($A3,laziki!B:B,laziki!D:D) -> 2054 | L3: =YEAR(B3) -> 2056 | M3: =L3-K3 -> 2 | N3: =IF(NOT(ISERROR(SEARCH("S",D3))),"S","N") -> N | O3: =IF(NOT(ISERROR(SEARCH("S",J3))),"S","N") -> N | P3: jeśli lazik nie ma wartosci 0 w roznicy lat to znaczy ze nie pracowal w tym samym roku
A4: 47 | B4: 64210 | C4: MC-05 | D4: 45.57N, 3.30E | E4: 9 | F4: 23366 | G4: =IF($E4 <= 100,F4,0) -> 23366 | H4: =_xlfn.XLOOKUP(C4,obszary!A:A,obszary!B:B) -> Ismenius Lacus | I4: =_xlfn.XLOOKUP($A4,laziki!B:B,laziki!C:C) -> Spirit 14 | J4: =_xlfn.XLOOKUP(I4,laziki!C:C,laziki!E:E) -> 27.30N, 17.48W | K4: =_xlfn.XLOOKUP($A4,laziki!B:B,laziki!D:D) -> 2065 | L4: =YEAR(B4) -> 2075 | M4: =L4-K4 -> 10 | N4: =IF(NOT(ISERROR(SEARCH("S",D4))),"S","N") -> N | O4: =IF(NOT(ISERROR(SEARCH("S",J4))),"S","N") -> N | S4: Największa ilość do 100m : | T4: =MAX(G:G) -> 101649
A5: 27 | B5: 58310 | C5: MC-29 | D5: 53.79S, 121.01E | E5: 169 | F5: 72463 | G5: =IF($E5 <= 100,F5,0) -> 0 | H5: =_xlfn.XLOOKUP(C5,obszary!A:A,obszary!B:B) -> Eridania | I5: =_xlfn.XLOOKUP($A5,laziki!B:B,laziki!C:C) -> Phobos 6 | J5: =_xlfn.XLOOKUP(I5,laziki!C:C,laziki!E:E) -> 74.62S, 100.08E | K5: =_xlfn.XLOOKUP($A5,laziki!B:B,laziki!D:D) -> 2054 | L5: =YEAR(B5) -> 2059 | M5: =L5-K5 -> 5 | N5: =IF(NOT(ISERROR(SEARCH("S",D5))),"S","N") -> S | O5: =IF(NOT(ISERROR(SEARCH("S",J5))),"S","N") -> S
A6: 19 | B6: 58007 | C6: MC-07 | D6: 42.75N, 158.49E | E6: 96 | F6: 3022 | G6: =IF($E6 <= 100,F6,0) -> 3022 | H6: =_xlfn.XLOOKUP(C6,obszary!A:A,obszary!B:B) -> Cebrenia | I6: =_xlfn.XLOOKUP($A6,laziki!B:B,laziki!C:C) -> Viking 13 | J6: =_xlfn.XLOOKUP(I6,laziki!C:C,laziki!E:E) -> 47.43N, 160.74E | K6: =_xlfn.XLOOKUP($A6,laziki!B:B,laziki!D:D) -> 2056 | L6: =YEAR(B6) -> 2058 | M6: =L6-K6 -> 2 | N6: =IF(NOT(ISERROR(SEARCH("S",D6))),"S","N") -> N | O6: =IF(NOT(ISERROR(SEARCH("S",J6))),"S","N") -> N
A7: 101 | B7: 63035 | C7: MC-07 | D7: 40.88N, 162.15E | E7: 1270 | F7: 2461 | G7: =IF($E7 <= 100,F7,0) -> 0 | H7: =_xlfn.XLOOKUP(C7,obszary!A:A,obszary!B:B) -> Cebrenia | I7: =_xlfn.XLOOKUP($A7,laziki!B:B,laziki!C:C) -> Perseverance 8 | J7: =_xlfn.XLOOKUP(I7,laziki!C:C,laziki!E:E) -> 53.93N, 163.34E | K7: =_xlfn.XLOOKUP($A7,laziki!B:B,laziki!D:D) -> 2071 | L7: =YEAR(B7) -> 2072 | M7: =L7-K7 -> 1 | N7: =IF(NOT(ISERROR(SEARCH("S",D7))),"S","N") -> N | O7: =IF(NOT(ISERROR(SEARCH("S",J7))),"S","N") -> N
A8: 12 | B8: 58007 | C8: MC-09 | D8: 6.42N, 119.66W | E8: 45 | F8: 3764 | G8: =IF($E8 <= 100,F8,0) -> 3764 | H8: =_xlfn.XLOOKUP(C8,obszary!A:A,obszary!B:B) -> Tharsis | I8: =_xlfn.XLOOKUP($A8,laziki!B:B,laziki!C:C) -> Mariner 20 | J8: =_xlfn.XLOOKUP(I8,laziki!C:C,laziki!E:E) -> 6.41S, 116.10W | K8: =_xlfn.XLOOKUP($A8,laziki!B:B,laziki!D:D) -> 2055 | L8: =YEAR(B8) -> 2058 | M8: =L8-K8 -> 3 | N8: =IF(NOT(ISERROR(SEARCH("S",D8))),"S","N") -> N | O8: =IF(NOT(ISERROR(SEARCH("S",J8))),"S","N") -> S
A9: 82 | B9: 62871 | C9: MC-23 | D9: 21.38S, 171.49E | E9: 137 | F9: 8000 | G9: =IF($E9 <= 100,F9,0) -> 0 | H9: =_xlfn.XLOOKUP(C9,obszary!A:A,obszary!B:B) -> Aeolis | I9: =_xlfn.XLOOKUP($A9,laziki!B:B,laziki!C:C) -> Phoenix 7 | J9: =_xlfn.XLOOKUP(I9,laziki!C:C,laziki!E:E) -> 42.36S, 157.15E | K9: =_xlfn.XLOOKUP($A9,laziki!B:B,laziki!D:D) -> 2068 | L9: =YEAR(B9) -> 2072 | M9: =L9-K9 -> 4 | N9: =IF(NOT(ISERROR(SEARCH("S",D9))),"S","N") -> S | O9: =IF(NOT(ISERROR(SEARCH("S",J9))),"S","N") -> S
A10: 7 | B10: 57341 | C10: MC-04 | D10: 37.86N, 40.31W | E10: 163 | F10: 6006 | G10: =IF($E10 <= 100,F10,0) -> 0 | H10: =_xlfn.XLOOKUP(C10,obszary!A:A,obszary!B:B) -> Mare Acidalium | I10: =_xlfn.XLOOKUP($A10,laziki!B:B,laziki!C:C) -> Mariner 12 | J10: =_xlfn.XLOOKUP(I10,laziki!C:C,laziki!E:E) -> 53.29N, 45.78W | K10: =_xlfn.XLOOKUP($A10,laziki!B:B,laziki!D:D) -> 2053 | L10: =YEAR(B10) -> 2056 | M10: =L10-K10 -> 3 | N10: =IF(NOT(ISERROR(SEARCH("S",D10))),"S","N") -> N | O10: =IF(NOT(ISERROR(SEARCH("S",J10))),"S","N") -> N
A11: 79 | B11: 64329 | C11: MC-06 | D11: 36.31N, 103.41E | E11: 252 | F11: 4902 | G11: =IF($E11 <= 100,F11,0) -> 0 | H11: =_xlfn.XLOOKUP(C11,obszary!A:A,obszary!B:B) -> Casius | I11: =_xlfn.XLOOKUP($A11,laziki!B:B,laziki!C:C) -> Rosetta 29 | J11: =_xlfn.XLOOKUP(I11,laziki!C:C,laziki!E:E) -> 18.24N, 120.68E | K11: =_xlfn.XLOOKUP($A11,laziki!B:B,laziki!D:D) -> 2073 | L11: =YEAR(B11) -> 2076 | M11: =L11-K11 -> 3 | N11: =IF(NOT(ISERROR(SEARCH("S",D11))),"S","N") -> N | O11: =IF(NOT(ISERROR(SEARCH("S",J11))),"S","N") -> N
A12: 2 | B12: 55776 | C12: MC-22 | D12: 11.95S, 122.63E | E12: 124 | F12: 1788 | G12: =IF($E12 <= 100,F12,0) -> 0 | H12: =_xlfn.XLOOKUP(C12,obszary!A:A,obszary!B:B) -> Mare Tyrrhenum | I12: =_xlfn.XLOOKUP($A12,laziki!B:B,laziki!C:C) -> Mariner 6 | J12: =_xlfn.XLOOKUP(I12,laziki!C:C,laziki!E:E) -> 11.90N, 119.49E | K12: =_xlfn.XLOOKUP($A12,laziki!B:B,laziki!D:D) -> 2050 | L12: =YEAR(B12) -> 2052 | M12: =L12-K12 -> 2 | N12: =IF(NOT(ISERROR(SEARCH("S",D12))),"S","N") -> S | O12: =IF(NOT(ISERROR(SEARCH("S",J12))),"S","N") -> N
A13: 39 | B13: 61195 | C13: MC-24 | D13: 47.29S, 178.82W | E13: 482 | F13: 3313 | G13: =IF($E13 <= 100,F13,0) -> 0 | H13: =_xlfn.XLOOKUP(C13,obszary!A:A,obszary!B:B) -> Phaethontis | I13: =_xlfn.XLOOKUP($A13,laziki!B:B,laziki!C:C) -> Pathfinder 9 | J13: =_xlfn.XLOOKUP(I13,laziki!C:C,laziki!E:E) -> 59.92S, 179.01W | K13: =_xlfn.XLOOKUP($A13,laziki!B:B,laziki!D:D) -> 2062 | L13: =YEAR(B13) -> 2067 | M13: =L13-K13 -> 5 | N13: =IF(NOT(ISERROR(SEARCH("S",D13))),"S","N") -> S | O13: =IF(NOT(ISERROR(SEARCH("S",J13))),"S","N") -> S
A14: 22 | B14: 56620 | C14: MC-12 | D14: 27.63N, 36.90E | E14: 128 | F14: 6832 | G14: =IF($E14 <= 100,F14,0) -> 0 | H14: =_xlfn.XLOOKUP(C14,obszary!A:A,obszary!B:B) -> Arabia | I14: =_xlfn.XLOOKUP($A14,laziki!B:B,laziki!C:C) -> Phobos 1 | J14: =_xlfn.XLOOKUP(I14,laziki!C:C,laziki!E:E) -> 5.89N, 39.91E | K14: =_xlfn.XLOOKUP($A14,laziki!B:B,laziki!D:D) -> 2053 | L14: =YEAR(B14) -> 2055 | M14: =L14-K14 -> 2 | N14: =IF(NOT(ISERROR(SEARCH("S",D14))),"S","N") -> N | O14: =IF(NOT(ISERROR(SEARCH("S",J14))),"S","N") -> N
A15: 42 | B15: 62353 | C15: MC-15 | D15: 22.21N, 175.94E | E15: 88 | F15: 4076 | G15: =IF($E15 <= 100,F15,0) -> 4076 | H15: =_xlfn.XLOOKUP(C15,obszary!A:A,obszary!B:B) -> Elysium | I15: =_xlfn.XLOOKUP($A15,laziki!B:B,laziki!C:C) -> Spirit 6 | J15: =_xlfn.XLOOKUP(I15,laziki!C:C,laziki!E:E) -> 27.80N, 160.30E | K15: =_xlfn.XLOOKUP($A15,laziki!B:B,laziki!D:D) -> 2063 | L15: =YEAR(B15) -> 2070 | M15: =L15-K15 -> 7 | N15: =IF(NOT(ISERROR(SEARCH("S",D15))),"S","N") -> N | O15: =IF(NOT(ISERROR(SEARCH("S",J15))),"S","N") -> N
A16: 61 | B16: 63606 | C16: MC-26 | D16: 56.95S, 10.43W | E16: 103 | F16: 19313 | G16: =IF($E16 <= 100,F16,0) -> 0 | H16: =_xlfn.XLOOKUP(C16,obszary!A:A,obszary!B:B) -> Argyre | I16: =_xlfn.XLOOKUP($A16,laziki!B:B,laziki!C:C) -> Opportunity 19 | J16: =_xlfn.XLOOKUP(I16,laziki!C:C,laziki!E:E) -> 68.17S, 21.83W | K16: =_xlfn.XLOOKUP($A16,laziki!B:B,laziki!D:D) -> 2069 | L16: =YEAR(B16) -> 2074 | M16: =L16-K16 -> 5 | N16: =IF(NOT(ISERROR(SEARCH("S",D16))),"S","N") -> S | O16: =IF(NOT(ISERROR(SEARCH("S",J16))),"S","N") -> S
... A5180: 95 | B5180: 61826 | C5180: MC-18 | D5180: 9.71S, 77.64W | E5180: 82 | F5180: 2324 | G5180: =IF($E5180 <= 100,F5180,0) -> 2324 | H5180: =_xlfn.XLOOKUP(C5180,obszary!A:A,obszary!B:B) -> Coprates | I5180: =_xlfn.XLOOKUP($A5180,laziki!B:B,laziki!C:C) -> Dawn 6 | J5180: =_xlfn.XLOOKUP(I5180,laziki!C:C,laziki!E:E) -> 8.80N, 79.73W | K5180: =_xlfn.XLOOKUP($A5180,laziki!B:B,laziki!D:D) -> 2067 | L5180: =YEAR(B5180) -> 2069 | M5180: =L5180-K5180 -> 2 | N5180: =IF(NOT(ISERROR(SEARCH("S",D5180))),"S","N") -> S | O5180: =IF(NOT(ISERROR(SEARCH("S",J5180))),"S","N") -> N

Sheet obszary
A1: kod_obszaru | B1: nazwa_obszaru
A2: MC-01 | B2: Mare Boreum
A3: MC-02 | B3: Diacria
A4: MC-03 | B4: Arcadia
A5: MC-04 | B5: Mare Acidalium
A6: MC-05 | B6: Ismenius Lacus
A7: MC-06 | B7: Casius
A8: MC-07 | B8: Cebrenia
A9: MC-08 | B9: Amazonis
A10: MC-09 | B10: Tharsis
A11: MC-10 | B11: Lunae Palus
A12: MC-11 | B12: Oxia Palus
... A31: MC-30 | B31: Mare Australe

Sheet laziki
B2: nr_lazika | C2: nazwa_lazika | D2: rok_wyslania | E2: wsp_ladowania
B3: 1 | C3: Mariner 3 | D3: 2049 | E3: 50.51N, 70.01E
B4: 2 | C4: Mariner 6 | D4: 2050 | E4: 11.90N, 119.49E
B5: 3 | C5: Mariner 7 | D5: 2050 | E5: 44.90S, 130.80W
B6: 4 | C6: Mariner 9 | D6: 2051 | E6: 43.20S, 21.89W
B7: 5 | C7: Mariner 10 | D7: 2051 | E7: 4.88N, 63.43E
B8: 6 | C8: Mariner 11 | D8: 2052 | E8: 77.71N, 148.53E
B9: 7 | C9: Mariner 12 | D9: 2053 | E9: 53.29N, 45.78W
B10: 8 | C10: Mariner 13 | D10: 2053 | E10: 57.37S, 25.45E
B11: 9 | C11: Mariner 14 | D11: 2054 | E11: 17.63S, 13.01W
B12: 10 | C12: Mariner 15 | D12: 2054 | E12: 23.79S, 56.97W
B13: 11 | C13: Mariner 16 | D13: 2055 | E13: 59.42S, 15.97W
B14: 12 | C14: Mariner 20 | D14: 2055 | E14: 6.41S, 116.10W
... B103: 101 | C103: Perseverance 8 | D103: 2071 | E103: 53.93N, 163.34E

Sheet Arkusz1
